Workbook

Sheet Summary
A1: AI Queries Finder - Coastline Epoxy Floors
A2: Google Search Console, Last 3 months (23 Jul - 21 Oct 2026). Built 2026-10-22.
A4: Site total clicks (no filter) | B4: 6840
A5: Site total impressions (no filter) | B5: 412000
A6: AI-style queries found | B6: =COUNTIF('AI Queries'!$C$2:$C$59,"Yes")
A7: AI-style impressions | B7: =SUMIFS('AI Queries'!$J$2:$J$59,'AI Queries'!$C$2:$C$59,"Yes")
A8: AI-style clicks | B8: =SUMIFS('AI Queries'!$I$2:$I$59,'AI Queries'!$C$2:$C$59,"Yes")
A9: AI-style CTR | B9: =IF(B7>0,B8/B7,0)
A10: Share of site impressions | B10: =IF(N(B5)>0,B7/B5,"n/a")
A11: Queries where an AI answer likely takes the click | B11: =COUNTIFS('AI Queries'!$C$2:$C$59,"Yes",'AI Queries'!$N$2:$N$59,"Yes")
A12: Topic clusters | B12: =COUNTA('Topic Clusters'!$A$2:$A$11)
A13: Est. extra clicks if the plan works (per period) | B13: =SUMIFS('AI Queries'!$Q$2:$Q$59,'AI Queries'!$C$2:$C$59,"Yes")
A15: The short version
A16: About 7% of the site's impressions come from AI-style questions, and most land on pages that rank but don't answer the question in one quotable passage. Cost and lifespan questions already rank in the top 8, yet CTR is a fraction of what those positions earn: AI Overviews are answering them. The biggest move is answer-first blocks with real Gold Coast numbers on the cost and garage pages this week.
A18: Top topics
A19: Topic | B19: Priority | C19: Impressions | D19: Clicks | E19: Avg position | F19: Est. extra clicks | G19: Move
A20: ='Topic Clusters'!B2 | B20: ='Topic Clusters'!C2 | C20: ='Topic Clusters'!F2 | D20: ='Topic Clusters'!E2 | E20: ='Topic Clusters'!H2 | F20: ='Topic Clusters'!K2 | G20: Update existing page
A21: ='Topic Clusters'!B3 | B21: ='Topic Clusters'!C3 | C21: ='Topic Clusters'!F3 | D21: ='Topic Clusters'!E3 | E21: ='Topic Clusters'!H3 | F21: ='Topic Clusters'!K3 | G21: Update existing page
A22: ='Topic Clusters'!B4 | B22: ='Topic Clusters'!C4 | C22: ='Topic Clusters'!F4 | D22: ='Topic Clusters'!E4 | E22: ='Topic Clusters'!H4 | F22: ='Topic Clusters'!K4 | G22: New section
A23: ='Topic Clusters'!B5 | B23: ='Topic Clusters'!C5 | C23: ='Topic Clusters'!F5 | D23: ='Topic Clusters'!E5 | E23: ='Topic Clusters'!H5 | F23: ='Topic Clusters'!K5 | G23: Update existing page
A24: ='Topic Clusters'!B6 | B24: ='Topic Clusters'!C6 | C24: ='Topic Clusters'!F6 | D24: ='Topic Clusters'!E6 | E24: ='Topic Clusters'!H6 | F24: ='Topic Clusters'!K6 | G24: New section
A26: Quick wins (days 1-7)
A27: - Check robots.txt and the Cloudflare bot settings: allow OAI-SearchBot, ChatGPT-User, PerplexityBot, Claude-SearchBot and Bingbot
A28: - Verify the site in Bing Webmaster Tools (import from GSC) and switch on IndexNow
A29: - Add the T1 and T2 answer blocks + question headings to the cost and garage pages, then request indexing
A30: - Rewrite the cost page title to promise the specific answer: 'Epoxy Flooring Cost Gold Coast: m² Prices + Real Jobs'
A31: - Save the master regex as a GSC filter and note this report's baseline (impressions, clicks, CTR)
A33: How to use this sheet
A34: 1. Topic Clusters: what AI-style searchers want from you, biggest first.
A35: 2. Optimization Plan: the answer block, headings, FAQ and links to add per topic (green = review).
A36: 3. AI Visibility Plan: do the quick wins this week, then the 30/90-day plan. Fill the amber cells.
A37: 4. Regex Library: save the master regex as a GSC filter and re-check monthly against this baseline.
A38: Green cells are suggestions to review. Amber cells are yours to fill in.
A40: Built with ai-queries-finder by Akif Qureshi | SEO Specialist - algoblueprints.com

Sheet AI Queries
A1: Query | B1: Words | C1: AI-style | D1: AI score | E1: Tier | F1: Regex families | G1: Intent | H1: Topic | I1: Clicks | J1: Impressions | K1: CTR | L1: Position | M1: Bucket | N1: AI Overview likely | O1: Action type | P1: Target CTR | Q1: Est. extra clicks | R1: Page
A2: how much does epoxy flooring cost per square metre | B2: =IF(LEN(TRIM(A2))=0,0,LEN(TRIM(A2))-LEN(SUBSTITUTE(TRIM(A2)," ",""))+1) | C2: Yes | D2: 60 | E2: High | F2: R02, R03, R09 | G2: Transactional | H2: T1 | I2: 58 | J2: 3100 | K2: =IF(J2>0,I2/J2,0) | L2: 3 | M2: Top 3 | N2: Yes | O2: Win the AI citation (answer is likely summarised) | P2: 0.25 | Q2: =IF(H2="",0,MAX(0,ROUND(J2*P2-I2,0)))
A3: how long does epoxy garage floor last | B3: =IF(LEN(TRIM(A3))=0,0,LEN(TRIM(A3))-LEN(SUBSTITUTE(TRIM(A3)," ",""))+1) | C3: Yes | D3: 60 | E3: High | F3: R02, R03, R09 | G3: Informational | H3: T2 | I3: 72 | J3: 2400 | K3: =IF(J3>0,I3/J3,0) | L3: 2.1 | M3: Top 3 | N3: Yes | O3: Win the AI citation (answer is likely summarised) | P3: 0.25 | Q3: =IF(H3="",0,MAX(0,ROUND(J3*P3-I3,0)))
A4: is epoxy flooring worth it for a garage | B4: =IF(LEN(TRIM(A4))=0,0,LEN(TRIM(A4))-LEN(SUBSTITUTE(TRIM(A4)," ",""))+1) | C4: Yes | D4: 55 | E4: High | F4: R02, R03, R07 | G4: Commercial | H4: T3 | I4: 117 | J4: 1900 | K4: =IF(J4>0,I4/J4,0) | L4: 4.2 | M4: 4-10 | O4: Answer upgrade | P4: 0.1 | Q4: =IF(H4="",0,MAX(0,ROUND(J4*P4-I4,0)))
A5: how much does it cost to epoxy a double garage | B5: =IF(LEN(TRIM(A5))=0,0,LEN(TRIM(A5))-LEN(SUBSTITUTE(TRIM(A5)," ",""))+1) | C5: Yes | D5: 80 | E5: High | F5: R01, R03, R09 | G5: Transactional | H5: T1 | I5: 57 | J5: 1450 | K5: =IF(J5>0,I5/J5,0) | L5: 5.6 | M5: 4-10 | O5: Answer upgrade | P5: 0.1 | Q5: =IF(H5="",0,MAX(0,ROUND(J5*P5-I5,0)))
A6: what is the best epoxy for garage floors | B6: =IF(LEN(TRIM(A6))=0,0,LEN(TRIM(A6))-LEN(SUBSTITUTE(TRIM(A6)," ",""))+1) | C6: Yes | D6: 70 | E6: High | F6: R02, R03, R07, R09 | G6: Commercial | H6: T3 | I6: 18 | J6: 1300 | K6: =IF(J6>0,I6/J6,0) | L6: 8.9 | M6: 4-10 | O6: Answer upgrade | P6: 0.1 | Q6: =IF(H6="",0,MAX(0,ROUND(J6*P6-I6,0)))
A7: what is flake epoxy flooring | B7: =IF(LEN(TRIM(A7))=0,0,LEN(TRIM(A7))-LEN(SUBSTITUTE(TRIM(A7)," ",""))+1) | C7: Yes | D7: 45 | E7: Medium | F7: R03, R09 | G7: Informational | H7: T10 | I7: 31 | J7: 1250 | K7: =IF(J7>0,I7/J7,0) | L7: 2.9 | M7: Top 3 | N7: Yes | O7: Win the AI citation (answer is likely summarised) | P7: 0.25 | Q7: =IF(H7="",0,MAX(0,ROUND(J7*P7-I7,0)))
A8: how do you clean an epoxy garage floor | B8: =IF(LEN(TRIM(A8))=0,0,LEN(TRIM(A8))-LEN(SUBSTITUTE(TRIM(A8)," ",""))+1) | C8: Yes | D8: 60 | E8: High | F8: R02, R03, R09 | G8: Informational | H8: T4 | I8: 33 | J8: 1100 | K8: =IF(J8>0,I8/J8,0) | L8: 2.6 | M8: Top 3 | N8: Yes | O8: Win the AI citation (answer is likely summarised) | P8: 0.25 | Q8: =IF(H8="",0,MAX(0,ROUND(J8*P8-I8,0)))
A9: is epoxy flooring slippery when wet | B9: =IF(LEN(TRIM(A9))=0,0,LEN(TRIM(A9))-LEN(SUBSTITUTE(TRIM(A9)," ",""))+1) | C9: Yes | D9: 30 | E9: Medium | F9: R03 | G9: Informational | H9: T6 | I9: 38 | J9: 980 | K9: =IF(J9>0,I9/J9,0) | L9: 5.3 | M9: 4-10 | O9: Answer upgrade | P9: 0.1 | Q9: =IF(H9="",0,MAX(0,ROUND(J9*P9-I9,0)))
A10: can you put epoxy over cracked concrete | B10: =IF(LEN(TRIM(A10))=0,0,LEN(TRIM(A10))-LEN(SUBSTITUTE(TRIM(A10)," ",""))+1) | C10: Yes | D10: 75 | E10: High | F10: R02, R03, R04 | G10: Informational | H10: T5 | I10: 9 | J10: 880 | K10: =IF(J10>0,I10/J10,0) | L10: 11.6 | M10: 11-20 | O10: Striking distance: expand + internal links | P10: 0.055 | Q10: =IF(H10="",0,MAX(0,ROUND(J10*P10-I10,0)))
A11: how long after epoxy can i drive on it | B11: =IF(LEN(TRIM(A11))=0,0,LEN(TRIM(A11))-LEN(SUBSTITUTE(TRIM(A11)," ",""))+1) | C11: Yes | D11: 80 | E11: High | F11: R02, R03, R05, R09 | G11: Informational | H11: T2 | I11: 18 | J11: 860 | K11: =IF(J11>0,I11/J11,0) | L11: 3.1 | M11: 4-10 | N11: Yes | O11: Win the AI citation (answer is likely summarised) | P11: 0.1 | Q11: =IF(H11="",0,MAX(0,ROUND(J11*P11-I11,0)))
A12: what is the cheapest way to resurface a garage floor | B12: =IF(LEN(TRIM(A12))=0,0,LEN(TRIM(A12))-LEN(SUBSTITUTE(TRIM(A12)," ",""))+1) | C12: Yes | D12: 90 | E12: High | F12: R01, R03, R07, R09 | G12: Informational | H12: T1 | I12: 5 | J12: 830 | K12: =IF(J12>0,I12/J12,0) | L12: 21.9 | M12: 21+ | O12: Content gap: new section or page | P12: 0.026 | Q12: =IF(H12="",0,MAX(0,ROUND(J12*P12-I12,0)))
A13: how to clean epoxy floors without making them slippery | B13: =IF(LEN(TRIM(A13))=0,0,LEN(TRIM(A13))-LEN(SUBSTITUTE(TRIM(A13)," ",""))+1) | C13: Yes | D13: 70 | E13: High | F13: R02, R03, R08, R09 | G13: Informational | H13: T4 | I13: 33 | J13: 720 | K13: =IF(J13>0,I13/J13,0) | L13: 6.1 | M13: 4-10 | O13: Answer upgrade | P13: 0.1 | Q13: =IF(H13="",0,MAX(0,ROUND(J13*P13-I13,0)))
A14: what flooring is best for a warehouse with forklifts | B14: =IF(LEN(TRIM(A14))=0,0,LEN(TRIM(A14))-LEN(SUBSTITUTE(TRIM(A14)," ",""))+1) | C14: Yes | D14: 55 | E14: High | F14: R02, R03, R07 | G14: Commercial | H14: T3 | I14: 3 | J14: 690 | K14: =IF(J14>0,I14/J14,0) | L14: 24.5 | M14: 21+ | O14: Content gap: new section or page | P14: 0.026 | Q14: =IF(H14="",0,MAX(0,ROUND(J14*P14-I14,0)))
A15: what is the difference between epoxy and polyaspartic coatings | B15: =IF(LEN(TRIM(A15))=0,0,LEN(TRIM(A15))-LEN(SUBSTITUTE(TRIM(A15)," ",""))+1) | C15: Yes | D15: 75 | E15: High | F15: R02, R03, R06, R09 | G15: Informational | H15: T3 | I15: 3 | J15: 640 | K15: =IF(J15>0,I15/J15,0) | L15: 16.3 | M15: 11-20 | O15: Striking distance: expand + internal links | P15: 0.055 | Q15: =IF(H15="",0,MAX(0,ROUND(J15*P15-I15,0)))
A16: how long does an epoxy floor last in a garage in queensland | B16: =IF(LEN(TRIM(A16))=0,0,LEN(TRIM(A16))-LEN(SUBSTITUTE(TRIM(A16)," ",""))+1) | C16: Yes | D16: 80 | E16: High | F16: R01, R03, R09 | G16: Local | H16: T2 | I16: 10 | J16: 610 | K16: =IF(J16>0,I16/J16,0) | L16: 3.4 | M16: 4-10 | N16: Yes | O16: Win the AI citation (answer is likely summarised) | P16: 0.1 | Q16: =IF(H16="",0,MAX(0,ROUND(J16*P16-I16,0)))
A17: can epoxy be applied over tiles | B17: =IF(LEN(TRIM(A17))=0,0,LEN(TRIM(A17))-LEN(SUBSTITUTE(TRIM(A17)," ",""))+1) | C17: Yes | D17: 30 | E17: Medium | F17: R03 | G17: Informational | H17: T7 | I17: 2 | J17: 600 | K17: =IF(J17>0,I17/J17,0) | L17: 28.4 | M17: 21+ | O17: Content gap: new section or page | P17: 0.026 | Q17: =IF(H17="",0,MAX(0,ROUND(J17*P17-I17,0)))
A18: is polished concrete better than epoxy for a home | B18: =IF(LEN(TRIM(A18))=0,0,LEN(TRIM(A18))-LEN(SUBSTITUTE(TRIM(A18)," ",""))+1) | C18: Yes | D18: 60 | E18: High | F18: R02, R03, R06 | G18: Commercial | H18: T8 | I18: 12 | J18: 530 | K18: =IF(J18>0,I18/J18,0) | L18: 8.4 | M18: 4-10 | O18: Answer upgrade | P18: 0.1 | Q18: =IF(H18="",0,MAX(0,ROUND(J18*P18-I18,0)))
A19: why is epoxy flooring so expensive | B19: =IF(LEN(TRIM(A19))=0,0,LEN(TRIM(A19))-LEN(SUBSTITUTE(TRIM(A19)," ",""))+1) | C19: Yes | D19: 45 | E19: Medium | F19: R03, R09 | G19: Informational | H19: T1 | I19: 5 | J19: 520 | K19: =IF(J19>0,I19/J19,0) | L19: 12.4 | M19: 11-20 | O19: Striking distance: expand + internal links | P19: 0.055 | Q19: =IF(H19="",0,MAX(0,ROUND(J19*P19-I19,0)))
A20: is epoxy flooring toxic once cured | B20: =IF(LEN(TRIM(A20))=0,0,LEN(TRIM(A20))-LEN(SUBSTITUTE(TRIM(A20)," ",""))+1) | C20: Yes | D20: 30 | E20: Medium | F20: R03 | G20: Informational | H20: T6 | I20: 2 | J20: 520 | K20: =IF(J20>0,I20/J20,0) | L20: 25.8 | M20: 21+ | O20: Content gap: new section or page | P20: 0.026 | Q20: =IF(H20="",0,MAX(0,ROUND(J20*P20-I20,0)))
A21: can i do epoxy flooring myself or should i hire a professional | B21: =IF(LEN(TRIM(A21))=0,0,LEN(TRIM(A21))-LEN(SUBSTITUTE(TRIM(A21)," ",""))+1) | C21: Yes | D21: 100 | E21: High | F21: R01, R03, R05, R07, R09 | G21: Transactional | H21: T10 | I21: 7 | J21: 480 | K21: =IF(J21>0,I21/J21,0) | L21: 10.9 | M21: 11-20 | O21: Striking distance: expand + internal links | P21: 0.055 | Q21: =IF(H21="",0,MAX(0,ROUND(J21*P21-I21,0)))
A22: is epoxy flooring good for a commercial kitchen | B22: =IF(LEN(TRIM(A22))=0,0,LEN(TRIM(A22))-LEN(SUBSTITUTE(TRIM(A22)," ",""))+1) | C22: Yes | D22: 45 | E22: Medium | F22: R02, R03 | G22: Informational | H22: T9 | I22: 5 | J22: 470 | K22: =IF(J22>0,I22/J22,0) | L22: 13.7 | M22: 11-20 | O22: Striking distance: expand + internal links | P22: 0.055 | Q22: =IF(H22="",0,MAX(0,ROUND(J22*P22-I22,0)))
A23: what should you not use on epoxy floors | B23: =IF(LEN(TRIM(A23))=0,0,LEN(TRIM(A23))-LEN(SUBSTITUTE(TRIM(A23)," ",""))+1) | C23: Yes | D23: 60 | E23: High | F23: R02, R03, R09 | G23: Informational | H23: T10 | I23: 30 | J23: 450 | K23: =IF(J23>0,I23/J23,0) | L23: 4.9 | M23: 4-10 | O23: Answer upgrade | P23: 0.1 | Q23: =IF(H23="",0,MAX(0,ROUND(J23*P23-I23,0)))
A24: is epoxy garage flooring worth the money or should i just paint it | B24: =IF(LEN(TRIM(A24))=0,0,LEN(TRIM(A24))-LEN(SUBSTITUTE(TRIM(A24)," ",""))+1) | C24: Yes | D24: 100 | E24: High | F24: R01, R03, R05, R09 | G24: Commercial | H24: T3 | I24: 12 | J24: 420 | K24: =IF(J24>0,I24/J24,0) | L24: 6.8 | M24: 4-10 | O24: Answer upgrade | P24: 0.1 | Q24: =IF(H24="",0,MAX(0,ROUND(J24*P24-I24,0)))
A25: does epoxy flooring add value to a house when selling | B25: =IF(LEN(TRIM(A25))=0,0,LEN(TRIM(A25))-LEN(SUBSTITUTE(TRIM(A25)," ",""))+1) | C25: Yes | D25: 65 | E25: High | F25: R01, R03 | G25: Informational | H25: T10 | I25: 2 | J25: 410 | K25: =IF(J25>0,I25/J25,0) | L25: 23.7 | M25: 21+ | O25: Content gap: new section or page | P25: 0.026 | Q25: =IF(H25="",0,MAX(0,ROUND(J25*P25-I25,0)))
A26: why does diy epoxy peel off garage floors | B26: =IF(LEN(TRIM(A26))=0,0,LEN(TRIM(A26))-LEN(SUBSTITUTE(TRIM(A26)," ",""))+1) | C26: Yes | D26: 60 | E26: High | F26: R02, R03, R09 | G26: Informational | H26: T5 | I26: 8 | J26: 390 | K26: =IF(J26>0,I26/J26,0) | L26: 9.4 | M26: 4-10 | O26: Answer upgrade | P26: 0.1 | Q26: =IF(H26="",0,MAX(0,ROUND(J26*P26-I26,0)))
A27: how much should i pay for epoxy flooring on the gold coast | B27: =IF(LEN(TRIM(A27))=0,0,LEN(TRIM(A27))-LEN(SUBSTITUTE(TRIM(A27)," ",""))+1) | C27: Yes | D27: 100 | E27: High | F27: R01, R03, R05, R09 | G27: Local | H27: T1 | I27: 8 | J27: 380 | K27: =IF(J27>0,I27/J27,0) | L27: 7.2 | M27: 4-10 | O27: Answer upgrade | P27: 0.1 | Q27: =IF(H27="",0,MAX(0,ROUND(J27*P27-I27,0)))
A28: which is better flake or metallic epoxy for a garage | B28: =IF(LEN(TRIM(A28))=0,0,LEN(TRIM(A28))-LEN(SUBSTITUTE(TRIM(A28)," ",""))+1) | C28: Yes | D28: 80 | E28: High | F28: R01, R03, R06 | G28: Commercial | H28: T3 | I28: 9 | J28: 360 | K28: =IF(J28>0,I28/J28,0) | L28: 9.1 | M28: 4-10 | O28: Answer upgrade | P28: 0.1 | Q28: =IF(H28="",0,MAX(0,ROUND(J28*P28-I28,0)))
... A30: should i fix cracks in concrete before epoxy | B30: =IF(LEN(TRIM(A30))=0,0,LEN(TRIM(A30))-LEN(SUBSTITUTE(TRIM(A30)," ",""))+1) | C30: Yes | D30: 80 | E30: High | F30: R02, R03, R05, R09 | G30: Informational | H30: T5 | I30: 4 | J30: 340 | K30: =IF(J30>0,I30/J30,0) | L30: 13 | M30: 11-20 | O30: Striking distance: expand + internal links | P30: 0.055 | Q30: =IF(H30="",0,MAX(0,ROUND(J30*P30-I30,0)))
A31: how long does epoxy take to cure before parking a car | B31: =IF(LEN(TRIM(A31))=0,0,LEN(TRIM(A31))-LEN(SUBSTITUTE(TRIM(A31)," ",""))+1) | C31: Yes | D31: 80 | E31: High | F31: R01, R03, R09 | G31: Informational | H31: T2 | I31: 5 | J31: 330 | K31: =IF(J31>0,I31/J31,0) | L31: 4.4 | M31: 4-10 | N31: Yes | O31: Win the AI citation (answer is likely summarised) | P31: 0.1 | Q31: =IF(H31="",0,MAX(0,ROUND(J31*P31-I31,0)))
A32: can i use vinegar to clean my epoxy floor | B32: =IF(LEN(TRIM(A32))=0,0,LEN(TRIM(A32))-LEN(SUBSTITUTE(TRIM(A32)," ",""))+1) | C32: Yes | D32: 80 | E32: High | F32: R02, R03, R05, R09 | G32: Informational | H32: T4 | I32: 15 | J32: 310 | K32: =IF(J32>0,I32/J32,0) | L32: 3.8 | M32: 4-10 | O32: Answer upgrade | P32: 0.1 | Q32: =IF(H32="",0,MAX(0,ROUND(J32*P32-I32,0)))
A33: how to remove tyre marks from epoxy garage floor | B33: =IF(LEN(TRIM(A33))=0,0,LEN(TRIM(A33))-LEN(SUBSTITUTE(TRIM(A33)," ",""))+1) | C33: Yes | D33: 60 | E33: High | F33: R02, R03, R09 | G33: Informational | H33: T4 | I33: 9 | J33: 290 | K33: =IF(J33>0,I33/J33,0) | L33: 7.7 | M33: 4-10 | O33: Answer upgrade | P33: 0.1 | Q33: =IF(H33="",0,MAX(0,ROUND(J33*P33-I33,0)))
A34: why is my epoxy floor peeling after one year | B34: =IF(LEN(TRIM(A34))=0,0,LEN(TRIM(A34))-LEN(SUBSTITUTE(TRIM(A34)," ",""))+1) | C34: Yes | D34: 80 | E34: High | F34: R02, R03, R05, R09 | G34: Informational | H34: T5 | I34: 1 | J34: 270 | K34: =IF(J34>0,I34/J34,0) | L34: 22 | M34: 21+ | O34: Content gap: new section or page | P34: 0.026 | Q34: =IF(H34="",0,MAX(0,ROUND(J34*P34-I34,0)))
A35: how thick should an epoxy garage floor be | B35: =IF(LEN(TRIM(A35))=0,0,LEN(TRIM(A35))-LEN(SUBSTITUTE(TRIM(A35)," ",""))+1) | C35: Yes | D35: 45 | E35: Medium | F35: R02, R03 | G35: Informational | H35: T7 | I35: 5 | J35: 270 | K35: =IF(J35>0,I35/J35,0) | L35: 9.6 | M35: 4-10 | O35: Answer upgrade | P35: 0.1 | Q35: =IF(H35="",0,MAX(0,ROUND(J35*P35-I35,0)))
A36: what affects the price of epoxy flooring | B36: =IF(LEN(TRIM(A36))=0,0,LEN(TRIM(A36))-LEN(SUBSTITUTE(TRIM(A36)," ",""))+1) | C36: Yes | D36: 45 | E36: Medium | F36: R02, R03 | G36: Transactional | H36: T1 | I36: 2 | J36: 260 | K36: =IF(J36>0,I36/J36,0) | L36: 14.1 | M36: 11-20 | O36: Striking distance: expand + internal links | P36: 0.055 | Q36: =IF(H36="",0,MAX(0,ROUND(J36*P36-I36,0)))
A37: what colour epoxy floor hides dirt best | B37: =IF(LEN(TRIM(A37))=0,0,LEN(TRIM(A37))-LEN(SUBSTITUTE(TRIM(A37)," ",""))+1) | C37: Yes | D37: 55 | E37: High | F37: R02, R03, R07 | G37: Commercial | H37: T3 | I37: 2 | J37: 240 | K37: =IF(J37>0,I37/J37,0) | L37: 15.5 | M37: 11-20 | O37: Striking distance: expand + internal links | P37: 0.055 | Q37: =IF(H37="",0,MAX(0,ROUND(J37*P37-I37,0)))
A38: how do i make my epoxy floor less slippery | B38: =IF(LEN(TRIM(A38))=0,0,LEN(TRIM(A38))-LEN(SUBSTITUTE(TRIM(A38)," ",""))+1) | C38: Yes | D38: 80 | E38: High | F38: R02, R03, R05, R09 | G38: Informational | H38: T6 | I38: 1 | J38: 230 | K38: =IF(J38>0,I38/J38,0) | L38: 18.5 | M38: 11-20 | O38: Striking distance: expand + internal links | P38: 0.055 | Q38: =IF(H38="",0,MAX(0,ROUND(J38*P38-I38,0)))
A39: what is commercial epoxy flooring used for | B39: =IF(LEN(TRIM(A39))=0,0,LEN(TRIM(A39))-LEN(SUBSTITUTE(TRIM(A39)," ",""))+1) | C39: Yes | D39: 60 | E39: High | F39: R02, R03, R09 | G39: Informational | H39: T9 | I39: 1 | J39: 210 | K39: =IF(J39>0,I39/J39,0) | L39: 17.8 | M39: 11-20 | O39: Striking distance: expand + internal links | P39: 0.055 | Q39: =IF(H39="",0,MAX(0,ROUND(J39*P39-I39,0)))
A40: i have cracks in my garage floor can i still get epoxy coating | B40: =IF(LEN(TRIM(A40))=0,0,LEN(TRIM(A40))-LEN(SUBSTITUTE(TRIM(A40)," ",""))+1) | C40: Yes | D40: 70 | E40: High | F40: R01, R05, R09 | G40: Informational | H40: T5 | I40: 1 | J40: 190 | K40: =IF(J40>0,I40/J40,0) | L40: 15.2 | M40: 11-20 | O40: Striking distance: expand + internal links | P40: 0.055 | Q40: =IF(H40="",0,MAX(0,ROUND(J40*P40-I40,0)))
A41: does epoxy flooring meet food safety standards in australia | B41: =IF(LEN(TRIM(A41))=0,0,LEN(TRIM(A41))-LEN(SUBSTITUTE(TRIM(A41)," ",""))+1) | C41: Yes | D41: 45 | E41: Medium | F41: R02, R03 | G41: Informational | H41: T6 | I41: 1 | J41: 180 | K41: =IF(J41>0,I41/J41,0) | L41: 21.3 | M41: 21+ | O41: Content gap: new section or page | P41: 0.026 | Q41: =IF(H41="",0,MAX(0,ROUND(J41*P41-I41,0)))
...

Sheet Regex Library
A1: Regex library
A2: Paste into GSC > Performance > + Add filter > Query > Custom (regex). RE2 syntax, max 4,096 characters.
A4: ID | B4: Family | C4: Regex (copy into GSC) | D4: Chars | E4: In master | F4: Weight | G4: What it catches | H4: AI queries | I4: Impressions | J4: Clicks
A5: R01 | B5: Long prompt (10+ words) | C5: ^\S+(\s+\S+){9,}$ | D5: =LEN(C5) | E5: Yes | F5: 35 | G5: Full-sentence prompts typed or passed through by AI assistants and AI Mode. The strongest single signal. | H5: =COUNTIFS('AI Queries'!$F$2:$F$59,"*"&A5&"*",'AI Queries'!$C$2:$C$59,"Yes") | I5: =SUMIFS('AI Queries'!$J$2:$J$59,'AI Queries'!$F$2:$F$59,"*"&A5&"*",'AI Queries'!$C$2:$C$59,"Yes") | J5: =SUMIFS('AI Queries'!$I$2:$I$59,'AI Queries'!$F$2:$F$59,"*"&A5&"*",'AI Queries'!$C$2:$C$59,"Yes")
A6: R02 | B6: Conversational length (7-9 words) | C6: ^\S+(\s+\S+){6,8}$ | D6: =LEN(C6) | E6: Yes | F6: 15 | G6: Queries longer than classic keywords but shorter than full prompts. | H6: =COUNTIFS('AI Queries'!$F$2:$F$59,"*"&A6&"*",'AI Queries'!$C$2:$C$59,"Yes") | I6: =SUMIFS('AI Queries'!$J$2:$J$59,'AI Queries'!$F$2:$F$59,"*"&A6&"*",'AI Queries'!$C$2:$C$59,"Yes") | J6: =SUMIFS('AI Queries'!$I$2:$I$59,'AI Queries'!$F$2:$F$59,"*"&A6&"*",'AI Queries'!$C$2:$C$59,"Yes")
A7: R03 | B7: Question opener | C7: (?i)^(who|whom|whose|what|whats|what's|when|where|why|how|which|is|are|was|were|am|can|could|should|would|will|do|does|did|has|have)\s | D7: =LEN(C7) | E7: Yes | F7: 30 | G7: Queries that start like a question to an assistant: what, how, why, can, should, is... | H7: =COUNTIFS('AI Queries'!$F$2:$F$59,"*"&A7&"*",'AI Queries'!$C$2:$C$59,"Yes") | I7: =SUMIFS('AI Queries'!$J$2:$J$59,'AI Queries'!$F$2:$F$59,"*"&A7&"*",'AI Queries'!$C$2:$C$59,"Yes") | J7: =SUMIFS('AI Queries'!$I$2:$I$59,'AI Queries'!$F$2:$F$59,"*"&A7&"*",'AI Queries'!$C$2:$C$59,"Yes")
A8: R04 | B8: Instruction / request | C8: (?i)^(give|show|tell|help|explain|list|compare|recommend|suggest|find|create|write|generate|make|summarise|summarize|describe|plan|calculate|teach|guide|walk|act|pretend|please|i need|i want|im looking|i'm looking|i am looking|looking for|can you|could you)\b | D8: =LEN(C8) | E8: Yes | F8: 30 | G8: Commands written for an AI: give me, explain, compare, list, write, help me, I need, I'm looking for... | H8: =COUNTIFS('AI Queries'!$F$2:$F$59,"*"&A8&"*",'AI Queries'!$C$2:$C$59,"Yes") | I8: =SUMIFS('AI Queries'!$J$2:$J$59,'AI Queries'!$F$2:$F$59,"*"&A8&"*",'AI Queries'!$C$2:$C$59,"Yes") | J8: =SUMIFS('AI Queries'!$I$2:$I$59,'AI Queries'!$F$2:$F$59,"*"&A8&"*",'AI Queries'!$C$2:$C$59,"Yes")
A9: R05 | B9: First-person context | C9: (?i)\b(i|im|i'm|ive|i've|my|me|we|our|mine)\b | D9: =LEN(C9) | E9: Yes | F9: 20 | G9: Personal situations people describe to an AI: my garage, I have, we need, our team... | H9: =COUNTIFS('AI Queries'!$F$2:$F$59,"*"&A9&"*",'AI Queries'!$C$2:$C$59,"Yes") | I9: =SUMIFS('AI Queries'!$J$2:$J$59,'AI Queries'!$F$2:$F$59,"*"&A9&"*",'AI Queries'!$C$2:$C$59,"Yes") | J9: =SUMIFS('AI Queries'!$I$2:$I$59,'AI Queries'!$F$2:$F$59,"*"&A9&"*",'AI Queries'!$C$2:$C$59,"Yes")
A10: R06 | B10: Comparison | C10: (?i)\b(vs|versus|compare|compared|comparison|alternative|alternatives|difference between|differences between|better than|pros and cons|which is better)\b | D10: =LEN(C10) | E10: No | F10: 15 | G10: X vs Y, alternatives, differences, pros and cons, which is better. | H10: =COUNTIFS('AI Queries'!$F$2:$F$59,"*"&A10&"*",'AI Queries'!$C$2:$C$59,"Yes") | I10: =SUMIFS('AI Queries'!$J$2:$J$59,'AI Queries'!$F$2:$F$59,"*"&A10&"*",'AI Queries'!$C$2:$C$59,"Yes") | J10: =SUMIFS('AI Queries'!$I$2:$I$59,'AI Queries'!$F$2:$F$59,"*"&A10&"*",'AI Queries'!$C$2:$C$59,"Yes")
A11: R07 | B11: Recommendation / best-of | C11: (?i)\b(best|top \d+|top rated|recommend|recommended|most reliable|most popular|most affordable|cheapest|worth it|should i (buy|use|choose|get|hire|go with))\b | D11: =LEN(C11) | E11: No | F11: 10 | G11: Best, top 10, recommended, worth it, should I buy/hire - the queries AI answers with shortlists of brands. | H11: =COUNTIFS('AI Queries'!$F$2:$F$59,"*"&A11&"*",'AI Queries'!$C$2:$C$59,"Yes") | I11: =SUMIFS('AI Queries'!$J$2:$J$59,'AI Queries'!$F$2:$F$59,"*"&A11&"*",'AI Queries'!$C$2:$C$59,"Yes") | J11: =SUMIFS('AI Queries'!$I$2:$I$59,'AI Queries'!$F$2:$F$59,"*"&A11&"*",'AI Queries'!$C$2:$C$59,"Yes")
A12: R08 | B12: Constraints & specifics | C12: (?i)\b(for beginners|for a small|for small|for my|for someone|step by step|under \$?\d+|less than|on a budget|without|checklist|template|example|examples|in 20\d\d|for 20\d\d)\b | D12: =LEN(C12) | E12: No | F12: 10 | G12: Extra conditions people add when they expect a tailored answer: for beginners, under $500, step by step, without, checklist. | H12: =COUNTIFS('AI Queries'!$F$2:$F$59,"*"&A12&"*",'AI Queries'!$C$2:$C$59,"Yes") | I12: =SUMIFS('AI Queries'!$J$2:$J$59,'AI Queries'!$F$2:$F$59,"*"&A12&"*",'AI Queries'!$C$2:$C$59,"Yes") | J12: =SUMIFS('AI Queries'!$I$2:$I$59,'AI Queries'!$F$2:$F$59,"*"&A12&"*",'AI Queries'!$C$2:$C$59,"Yes")
A13: R09 | B13: How / why / is-it reasoning | C13: (?i)\b(how (to|do|does|can|long|much|many|often)|why (is|do|does|are|would)|what (is|are|does|happens|should)|is it (safe|worth|possible|legal|true|normal|ok|okay|better)|does it|can i|should i|do i need)\b | D13: =LEN(C13) | E13: Yes | F13: 15 | G13: Explanation and decision questions anywhere in the query: how long, why does, is it worth, do I need, can I. | H13: =COUNTIFS('AI Queries'!$F$2:$F$59,"*"&A13&"*",'AI Queries'!$C$2:$C$59,"Yes") | I13: =SUMIFS('AI Queries'!$J$2:$J$59,'AI Queries'!$F$2:$F$59,"*"&A13&"*",'AI Queries'!$C$2:$C$59,"Yes") | J13: =SUMIFS('AI Queries'!$I$2:$I$59,'AI Queries'!$F$2:$F$59,"*"&A13&"*",'AI Queries'!$C$2:$C$59,"Yes")
A14: R10 | B14: AI tool mention / leaked prompt | C14: (?i)(chatgpt|chat gpt|openai|gpt-?[0-9]|gemini|claude|perplexity|copilot|ai overview|ai mode|\bllm\b|https?://|www\.|\.com/) | D14: =LEN(C14) | E14: Yes | F14: 40 | G14: Queries naming an AI tool, or URL-prefixed prompts like the ChatGPT queries reported leaking into GSC in late 2025. | H14: =COUNTIFS('AI Queries'!$F$2:$F$59,"*"&A14&"*",'AI Queries'!$C$2:$C$59,"Yes") | I14: =SUMIFS('AI Queries'!$J$2:$J$59,'AI Queries'!$F$2:$F$59,"*"&A14&"*",'AI Queries'!$C$2:$C$59,"Yes") | J14: =SUMIFS('AI Queries'!$I$2:$I$59,'AI Queries'!$F$2:$F$59,"*"&A14&"*",'AI Queries'!$C$2:$C$59,"Yes")
A15: MASTER | B15: Master regex (paste this first) | C15: (?i)^\S+(\s+\S+){9,}$|^\S+(\s+\S+){6,8}$|^(who|whom|whose|what|whats|what's|when|where|why|how|which|is|are|was|were|am|can|could|should|would|will|do|does|did|has|have)\s|^(give|show|tell|help|explain|list|compare|recommend|suggest|find|create|write|generate|make|summarise|summarize|describe|plan|calculate|teach|guide|walk|act|pretend|please|i need|i want|im looking|i'm looking|i am looking|looking for|can you|could you)\b|\b(i|im|i'm|ive|i've|my|me|we|our|mine)\b|\b(how (to|do|does|can|long|much|many|often)|why (is|do|does|are|would)|what (is|are|does|happens|should)|is it (safe|worth|possible|legal|true|normal|ok|okay|better)|does it|can i|should i|do i need)\b|(chatgpt|chat gpt|openai|gpt-?[0-9]|gemini|claude|perplexity|copilot|ai overview|ai mode|\bllm\b|https?://|www\.|\.com/) | D15: =LEN(C15) | E15: - | F15: - | G15: OR of every family marked 'in master'. Use it for the first pull; run single families to get past the 1,000-row cap. | H15: =COUNTIF('AI Queries'!$C$2:$C$59,"Yes") | I15: =SUMIFS('AI Queries'!$J$2:$J$59,'AI Queries'!$C$2:$C$59,"Yes") | J15: =SUMIFS('AI Queries'!$I$2:$I$59,'AI Queries'!$C$2:$C$59,"Yes")

Sheet Topic Clusters
A1: ID | B1: Topic | C1: Priority | D1: Queries | E1: Clicks | F1: Impressions | G1: CTR | H1: Avg position | I1: Avg AI score | J1: AI Overview likely | K1: Est. extra clicks | L1: Main intent | M1: Position buckets | N1: Pages | O1: Top queries
A2: T1 | B2: Cost & price | C2: High | D2: =COUNTIFS('AI Queries'!$H$2:$H$59,A2,'AI Queries'!$C$2:$C$59,"Yes") | E2: =SUMIFS('AI Queries'!$I$2:$I$59,'AI Queries'!$H$2:$H$59,A2) | F2: =SUMIFS('AI Queries'!$J$2:$J$59,'AI Queries'!$H$2:$H$59,A2) | G2: =IF(F2>0,E2/F2,0) | H2: 7.5 | I2: 62 | J2: =COUNTIFS('AI Queries'!$H$2:$H$59,A2,'AI Queries'!$N$2:$N$59,"Yes") | K2: =SUMIFS('AI Queries'!$Q$2:$Q$59,'AI Queries'!$H$2:$H$59,A2) | L2: Transactional | M2: 4-10 4, 11-20 2, Top 3 1, 21+ 1 | O2: how much does epoxy flooring cost per square metre how much does it cost to epoxy a double garage what is the cheapest way to resurface a garage floor why is epoxy flooring so expensive how much should i pay for epoxy flooring on the gold coast what affects the price of epoxy flooring epoxy flooring cost for a 6x6 garage with crack repair included chatgpt epoxy garage floor cost australia
A3: T2 | B3: How long / timing | C3: High | D3: =COUNTIFS('AI Queries'!$H$2:$H$59,A3,'AI Queries'!$C$2:$C$59,"Yes") | E3: =SUMIFS('AI Queries'!$I$2:$I$59,'AI Queries'!$H$2:$H$59,A3) | F3: =SUMIFS('AI Queries'!$J$2:$J$59,'AI Queries'!$H$2:$H$59,A3) | G3: =IF(F3>0,E3/F3,0) | H3: 2.7 | I3: 75 | J3: =COUNTIFS('AI Queries'!$H$2:$H$59,A3,'AI Queries'!$N$2:$N$59,"Yes") | K3: =SUMIFS('AI Queries'!$Q$2:$Q$59,'AI Queries'!$H$2:$H$59,A3) | L3: Informational | M3: 4-10 3, Top 3 1 | O3: how long does epoxy garage floor last how long after epoxy can i drive on it how long does an epoxy floor last in a garage in queensland how long does epoxy take to cure before parking a car
A4: T3 | B4: Choosing & comparing: company | C4: High | D4: =COUNTIFS('AI Queries'!$H$2:$H$59,A4,'AI Queries'!$C$2:$C$59,"Yes") | E4: =SUMIFS('AI Queries'!$I$2:$I$59,'AI Queries'!$H$2:$H$59,A4) | F4: =SUMIFS('AI Queries'!$J$2:$J$59,'AI Queries'!$H$2:$H$59,A4) | G4: =IF(F4>0,E4/F4,0) | H4: 10.1 | I4: 67 | J4: =COUNTIFS('AI Queries'!$H$2:$H$59,A4,'AI Queries'!$N$2:$N$59,"Yes") | K4: =SUMIFS('AI Queries'!$Q$2:$Q$59,'AI Queries'!$H$2:$H$59,A4) | L4: Commercial | M4: 4-10 7, 11-20 2, 21+ 1 | O4: is epoxy flooring worth it for a garage what is the best epoxy for garage floors what flooring is best for a warehouse with forklifts what is the difference between epoxy and polyaspartic coatings is epoxy garage flooring worth the money or should i just paint it which is better flake or metallic epoxy for a garage what colour epoxy floor hides dirt best compare epoxy flooring companies on the gold coast
A5: T4 | B5: Cleaning & care | C5: Medium | D5: =COUNTIFS('AI Queries'!$H$2:$H$59,A5,'AI Queries'!$C$2:$C$59,"Yes") | E5: =SUMIFS('AI Queries'!$I$2:$I$59,'AI Queries'!$H$2:$H$59,A5) | F5: =SUMIFS('AI Queries'!$J$2:$J$59,'AI Queries'!$H$2:$H$59,A5) | G5: =IF(F5>0,E5/F5,0) | H5: 5.5 | I5: 67 | J5: =COUNTIFS('AI Queries'!$H$2:$H$59,A5,'AI Queries'!$N$2:$N$59,"Yes") | K5: =SUMIFS('AI Queries'!$Q$2:$Q$59,'AI Queries'!$H$2:$H$59,A5) | L5: Informational | M5: 4-10 3, 11-20 2, Top 3 1 | O5: how do you clean an epoxy garage floor how to clean epoxy floors without making them slippery can i use vinegar to clean my epoxy floor how to remove tyre marks from epoxy garage floor is metallic epoxy hard to maintain i want a durable garage floor that looks good and is easy to clean what are my options
A6: T5 | B6: Problems & fixes: concrete | C6: Medium | D6: =COUNTIFS('AI Queries'!$H$2:$H$59,A6,'AI Queries'!$C$2:$C$59,"Yes") | E6: =SUMIFS('AI Queries'!$I$2:$I$59,'AI Queries'!$H$2:$H$59,A6) | F6: =SUMIFS('AI Queries'!$J$2:$J$59,'AI Queries'!$H$2:$H$59,A6) | G6: =IF(F6>0,E6/F6,0) | H6: 13.9 | I6: 67 | J6: =COUNTIFS('AI Queries'!$H$2:$H$59,A6,'AI Queries'!$N$2:$N$59,"Yes") | K6: =SUMIFS('AI Queries'!$Q$2:$Q$59,'AI Queries'!$H$2:$H$59,A6) | L6: Informational | M6: 11-20 3, 21+ 2, 4-10 1 | O6: can you put epoxy over cracked concrete why does diy epoxy peel off garage floors should i fix cracks in concrete before epoxy why is my epoxy floor peeling after one year i have cracks in my garage floor can i still get epoxy coating my epoxy floor has bubbles what went wrong
A7: T6 | B7: Safety & standards | C7: Medium | D7: =COUNTIFS('AI Queries'!$H$2:$H$59,A7,'AI Queries'!$C$2:$C$59,"Yes") | E7: =SUMIFS('AI Queries'!$I$2:$I$59,'AI Queries'!$H$2:$H$59,A7) | F7: =SUMIFS('AI Queries'!$J$2:$J$59,'AI Queries'!$H$2:$H$59,A7) | G7: =IF(F7>0,E7/F7,0) | H7: 14 | I7: 46 | J7: =COUNTIFS('AI Queries'!$H$2:$H$59,A7,'AI Queries'!$N$2:$N$59,"Yes") | K7: =SUMIFS('AI Queries'!$Q$2:$Q$59,'AI Queries'!$H$2:$H$59,A7) | L7: Informational | M7: 21+ 2, 4-10 1, 11-20 1 | O7: is epoxy flooring slippery when wet is epoxy flooring toxic once cured how do i make my epoxy floor less slippery does epoxy flooring meet food safety standards in australia
A8: T7 | B8: General epoxy questions | C8: Medium | D8: =COUNTIFS('AI Queries'!$H$2:$H$59,A8,'AI Queries'!$C$2:$C$59,"Yes") | E8: =SUMIFS('AI Queries'!$I$2:$I$59,'AI Queries'!$H$2:$H$59,A8) | F8: =SUMIFS('AI Queries'!$J$2:$J$59,'AI Queries'!$H$2:$H$59,A8) | G8: =IF(F8>0,E8/F8,0) | H8: 23.3 | I8: 58 | J8: =COUNTIFS('AI Queries'!$H$2:$H$59,A8,'AI Queries'!$N$2:$N$59,"Yes") | K8: =SUMIFS('AI Queries'!$Q$2:$Q$59,'AI Queries'!$H$2:$H$59,A8) | L8: Informational | M8: 21+ 2, 11-20 2, 4-10 1 | O8: can epoxy be applied over tiles can you epoxy a pool deck or outdoor patio how thick should an epoxy garage floor be explain the steps of applying epoxy flooring give me a checklist for preparing a garage floor for epoxy
A9: T8 | B9: Concrete: polished | C9: Medium | D9: =COUNTIFS('AI Queries'!$H$2:$H$59,A9,'AI Queries'!$C$2:$C$59,"Yes") | E9: =SUMIFS('AI Queries'!$I$2:$I$59,'AI Queries'!$H$2:$H$59,A9) | F9: =SUMIFS('AI Queries'!$J$2:$J$59,'AI Queries'!$H$2:$H$59,A9) | G9: =IF(F9>0,E9/F9,0) | H9: 10.9 | I9: 80 | J9: =COUNTIFS('AI Queries'!$H$2:$H$59,A9,'AI Queries'!$N$2:$N$59,"Yes") | K9: =SUMIFS('AI Queries'!$Q$2:$Q$59,'AI Queries'!$H$2:$H$59,A9) | L9: Commercial | M9: 4-10 1, 11-20 1 | O9: is polished concrete better than epoxy for a home should i choose epoxy or polished concrete for my house in a humid climate
A10: T9 | B10: Commercial | C10: Low | D10: =COUNTIFS('AI Queries'!$H$2:$H$59,A10,'AI Queries'!$C$2:$C$59,"Yes") | E10: =SUMIFS('AI Queries'!$I$2:$I$59,'AI Queries'!$H$2:$H$59,A10) | F10: =SUMIFS('AI Queries'!$J$2:$J$59,'AI Queries'!$H$2:$H$59,A10) | G10: =IF(F10>0,E10/F10,0) | H10: 15 | I10: 52 | J10: =COUNTIFS('AI Queries'!$H$2:$H$59,A10,'AI Queries'!$N$2:$N$59,"Yes") | K10: =SUMIFS('AI Queries'!$Q$2:$Q$59,'AI Queries'!$H$2:$H$59,A10) | L10: Informational | M10: 11-20 2 | O10: is epoxy flooring good for a commercial kitchen what is commercial epoxy flooring used for
A11: T10 | B11: Other AI-style queries | C11: Low | D11: =COUNTIFS('AI Queries'!$H$2:$H$59,A11,'AI Queries'!$C$2:$C$59,"Yes") | E11: =SUMIFS('AI Queries'!$I$2:$I$59,'AI Queries'!$H$2:$H$59,A11) | F11: =SUMIFS('AI Queries'!$J$2:$J$59,'AI Queries'!$H$2:$H$59,A11) | G11: =IF(F11>0,E11/F11,0) | H11: 9 | I11: 61 | J11: =COUNTIFS('AI Queries'!$H$2:$H$59,A11,'AI Queries'!$N$2:$N$59,"Yes") | K11: =SUMIFS('AI Queries'!$Q$2:$Q$59,'AI Queries'!$H$2:$H$59,A11) | L11: Informational | M11: 21+ 3, 11-20 2, Top 3 1, 4-10 1 | O11: what is flake epoxy flooring can i do epoxy flooring myself or should i hire a professional what should you not use on epoxy floors does epoxy flooring add value to a house when selling we are building a new home when should we epoxy the garage my garage floor gets wet in summer will epoxy still work according to ai what is the most durable garage floor coating

Sheet Opportunities
A1: Query | B1: Topic | C1: Intent | D1: Impressions | E1: Clicks | F1: CTR | G1: Position | H1: Bucket | I1: AI Overview likely | J1: Action type | K1: Target CTR | L1: Est. extra clicks | M1: Priority | N1: Page
A2: how much does epoxy flooring cost per square metre | B2: T1 | C2: Transactional | D2: 3100 | E2: 58 | F2: =IF(D2>0,E2/D2,0) | G2: 3 | H2: Top 3 | I2: Yes | J2: Win the AI citation (answer is likely summarised) | K2: 0.25 | L2: =MAX(0,ROUND(D2*K2-E2,0)) | M2: =IF(L2>=20,"High",IF(L2>=5,"Medium","Low"))
A3: how long does epoxy garage floor last | B3: T2 | C3: Informational | D3: 2400 | E3: 72 | F3: =IF(D3>0,E3/D3,0) | G3: 2.1 | H3: Top 3 | I3: Yes | J3: Win the AI citation (answer is likely summarised) | K3: 0.25 | L3: =MAX(0,ROUND(D3*K3-E3,0)) | M3: =IF(L3>=20,"High",IF(L3>=5,"Medium","Low"))
A4: what is flake epoxy flooring | B4: T10 | C4: Informational | D4: 1250 | E4: 31 | F4: =IF(D4>0,E4/D4,0) | G4: 2.9 | H4: Top 3 | I4: Yes | J4: Win the AI citation (answer is likely summarised) | K4: 0.25 | L4: =MAX(0,ROUND(D4*K4-E4,0)) | M4: =IF(L4>=20,"High",IF(L4>=5,"Medium","Low"))
A5: how do you clean an epoxy garage floor | B5: T4 | C5: Informational | D5: 1100 | E5: 33 | F5: =IF(D5>0,E5/D5,0) | G5: 2.6 | H5: Top 3 | I5: Yes | J5: Win the AI citation (answer is likely summarised) | K5: 0.25 | L5: =MAX(0,ROUND(D5*K5-E5,0)) | M5: =IF(L5>=20,"High",IF(L5>=5,"Medium","Low"))
A6: what is the best epoxy for garage floors | B6: T3 | C6: Commercial | D6: 1300 | E6: 18 | F6: =IF(D6>0,E6/D6,0) | G6: 8.9 | H6: 4-10 | J6: Answer upgrade | K6: 0.1 | L6: =MAX(0,ROUND(D6*K6-E6,0)) | M6: =IF(L6>=20,"High",IF(L6>=5,"Medium","Low"))
A7: how much does it cost to epoxy a double garage | B7: T1 | C7: Transactional | D7: 1450 | E7: 57 | F7: =IF(D7>0,E7/D7,0) | G7: 5.6 | H7: 4-10 | J7: Answer upgrade | K7: 0.1 | L7: =MAX(0,ROUND(D7*K7-E7,0)) | M7: =IF(L7>=20,"High",IF(L7>=5,"Medium","Low"))
A8: is epoxy flooring worth it for a garage | B8: T3 | C8: Commercial | D8: 1900 | E8: 117 | F8: =IF(D8>0,E8/D8,0) | G8: 4.2 | H8: 4-10 | J8: Answer upgrade | K8: 0.1 | L8: =MAX(0,ROUND(D8*K8-E8,0)) | M8: =IF(L8>=20,"High",IF(L8>=5,"Medium","Low"))
A9: how long after epoxy can i drive on it | B9: T2 | C9: Informational | D9: 860 | E9: 18 | F9: =IF(D9>0,E9/D9,0) | G9: 3.1 | H9: 4-10 | I9: Yes | J9: Win the AI citation (answer is likely summarised) | K9: 0.1 | L9: =MAX(0,ROUND(D9*K9-E9,0)) | M9: =IF(L9>=20,"High",IF(L9>=5,"Medium","Low"))
A10: is epoxy flooring slippery when wet | B10: T6 | C10: Informational | D10: 980 | E10: 38 | F10: =IF(D10>0,E10/D10,0) | G10: 5.3 | H10: 4-10 | J10: Answer upgrade | K10: 0.1 | L10: =MAX(0,ROUND(D10*K10-E10,0)) | M10: =IF(L10>=20,"High",IF(L10>=5,"Medium","Low"))
A11: how long does an epoxy floor last in a garage in queensland | B11: T2 | C11: Local | D11: 610 | E11: 10 | F11: =IF(D11>0,E11/D11,0) | G11: 3.4 | H11: 4-10 | I11: Yes | J11: Win the AI citation (answer is likely summarised) | K11: 0.1 | L11: =MAX(0,ROUND(D11*K11-E11,0)) | M11: =IF(L11>=20,"High",IF(L11>=5,"Medium","Low"))
A12: is polished concrete better than epoxy for a home | B12: T8 | C12: Commercial | D12: 530 | E12: 12 | F12: =IF(D12>0,E12/D12,0) | G12: 8.4 | H12: 4-10 | J12: Answer upgrade | K12: 0.1 | L12: =MAX(0,ROUND(D12*K12-E12,0)) | M12: =IF(L12>=20,"High",IF(L12>=5,"Medium","Low"))
A13: can you put epoxy over cracked concrete | B13: T5 | C13: Informational | D13: 880 | E13: 9 | F13: =IF(D13>0,E13/D13,0) | G13: 11.6 | H13: 11-20 | J13: Striking distance: expand + internal links | K13: 0.055 | L13: =MAX(0,ROUND(D13*K13-E13,0)) | M13: =IF(L13>=20,"High",IF(L13>=5,"Medium","Low"))
A14: how to clean epoxy floors without making them slippery | B14: T4 | C14: Informational | D14: 720 | E14: 33 | F14: =IF(D14>0,E14/D14,0) | G14: 6.1 | H14: 4-10 | J14: Answer upgrade | K14: 0.1 | L14: =MAX(0,ROUND(D14*K14-E14,0)) | M14: =IF(L14>=20,"High",IF(L14>=5,"Medium","Low"))
A15: what is the difference between epoxy and polyaspartic coatings | B15: T3 | C15: Informational | D15: 640 | E15: 3 | F15: =IF(D15>0,E15/D15,0) | G15: 16.3 | H15: 11-20 | J15: Striking distance: expand + internal links | K15: 0.055 | L15: =MAX(0,ROUND(D15*K15-E15,0)) | M15: =IF(L15>=20,"High",IF(L15>=5,"Medium","Low"))
A16: why does diy epoxy peel off garage floors | B16: T5 | C16: Informational | D16: 390 | E16: 8 | F16: =IF(D16>0,E16/D16,0) | G16: 9.4 | H16: 4-10 | J16: Answer upgrade | K16: 0.1 | L16: =MAX(0,ROUND(D16*K16-E16,0)) | M16: =IF(L16>=20,"High",IF(L16>=5,"Medium","Low"))
A17: is epoxy garage flooring worth the money or should i just paint it | B17: T3 | C17: Commercial | D17: 420 | E17: 12 | F17: =IF(D17>0,E17/D17,0) | G17: 6.8 | H17: 4-10 | J17: Answer upgrade | K17: 0.1 | L17: =MAX(0,ROUND(D17*K17-E17,0)) | M17: =IF(L17>=20,"High",IF(L17>=5,"Medium","Low"))
A18: how much should i pay for epoxy flooring on the gold coast | B18: T1 | C18: Local | D18: 380 | E18: 8 | F18: =IF(D18>0,E18/D18,0) | G18: 7.2 | H18: 4-10 | J18: Answer upgrade | K18: 0.1 | L18: =MAX(0,ROUND(D18*K18-E18,0)) | M18: =IF(L18>=20,"High",IF(L18>=5,"Medium","Low"))
A19: how long does epoxy take to cure before parking a car | B19: T2 | C19: Informational | D19: 330 | E19: 5 | F19: =IF(D19>0,E19/D19,0) | G19: 4.4 | H19: 4-10 | I19: Yes | J19: Win the AI citation (answer is likely summarised) | K19: 0.1 | L19: =MAX(0,ROUND(D19*K19-E19,0)) | M19: =IF(L19>=20,"High",IF(L19>=5,"Medium","Low"))
A20: which is better flake or metallic epoxy for a garage | B20: T3 | C20: Commercial | D20: 360 | E20: 9 | F20: =IF(D20>0,E20/D20,0) | G20: 9.1 | H20: 4-10 | J20: Answer upgrade | K20: 0.1 | L20: =MAX(0,ROUND(D20*K20-E20,0)) | M20: =IF(L20>=20,"High",IF(L20>=5,"Medium","Low"))
A21: why is epoxy flooring so expensive | B21: T1 | C21: Informational | D21: 520 | E21: 5 | F21: =IF(D21>0,E21/D21,0) | G21: 12.4 | H21: 11-20 | J21: Striking distance: expand + internal links | K21: 0.055 | L21: =MAX(0,ROUND(D21*K21-E21,0)) | M21: =IF(L21>=20,"High",IF(L21>=5,"Medium","Low"))
A22: how thick should an epoxy garage floor be | B22: T7 | C22: Informational | D22: 270 | E22: 5 | F22: =IF(D22>0,E22/D22,0) | G22: 9.6 | H22: 4-10 | J22: Answer upgrade | K22: 0.1 | L22: =MAX(0,ROUND(D22*K22-E22,0)) | M22: =IF(L22>=20,"High",IF(L22>=5,"Medium","Low"))
A23: is epoxy flooring good for a commercial kitchen | B23: T9 | C23: Informational | D23: 470 | E23: 5 | F23: =IF(D23>0,E23/D23,0) | G23: 13.7 | H23: 11-20 | J23: Striking distance: expand + internal links | K23: 0.055 | L23: =MAX(0,ROUND(D23*K23-E23,0)) | M23: =IF(L23>=20,"High",IF(L23>=5,"Medium","Low"))
A24: how to remove tyre marks from epoxy garage floor | B24: T4 | C24: Informational | D24: 290 | E24: 9 | F24: =IF(D24>0,E24/D24,0) | G24: 7.7 | H24: 4-10 | J24: Answer upgrade | K24: 0.1 | L24: =MAX(0,ROUND(D24*K24-E24,0)) | M24: =IF(L24>=20,"High",IF(L24>=5,"Medium","Low"))
A25: can i do epoxy flooring myself or should i hire a professional | B25: T10 | C25: Transactional | D25: 480 | E25: 7 | F25: =IF(D25>0,E25/D25,0) | G25: 10.9 | H25: 11-20 | J25: Striking distance: expand + internal links | K25: 0.055 | L25: =MAX(0,ROUND(D25*K25-E25,0)) | M25: =IF(L25>=20,"High",IF(L25>=5,"Medium","Low"))
A26: what is the cheapest way to resurface a garage floor | B26: T1 | C26: Informational | D26: 830 | E26: 5 | F26: =IF(D26>0,E26/D26,0) | G26: 21.9 | H26: 21+ | J26: Content gap: new section or page | K26: 0.026 | L26: =MAX(0,ROUND(D26*K26-E26,0)) | M26: =IF(L26>=20,"High",IF(L26>=5,"Medium","Low"))
A27: can i use vinegar to clean my epoxy floor | B27: T4 | C27: Informational | D27: 310 | E27: 15 | F27: =IF(D27>0,E27/D27,0) | G27: 3.8 | H27: 4-10 | J27: Answer upgrade | K27: 0.1 | L27: =MAX(0,ROUND(D27*K27-E27,0)) | M27: =IF(L27>=20,"High",IF(L27>=5,"Medium","Low"))
A28: what should you not use on epoxy floors | B28: T10 | C28: Informational | D28: 450 | E28: 30 | F28: =IF(D28>0,E28/D28,0) | G28: 4.9 | H28: 4-10 | J28: Answer upgrade | K28: 0.1 | L28: =MAX(0,ROUND(D28*K28-E28,0)) | M28: =IF(L28>=20,"High",IF(L28>=5,"Medium","Low"))
A29: what flooring is best for a warehouse with forklifts | B29: T3 | C29: Commercial | D29: 690 | E29: 3 | F29: =IF(D29>0,E29/D29,0) | G29: 24.5 | H29: 21+ | J29: Content gap: new section or page | K29: 0.026 | L29: =MAX(0,ROUND(D29*K29-E29,0)) | M29: =IF(L29>=20,"High",IF(L29>=5,"Medium","Low"))
A30: should i fix cracks in concrete before epoxy | B30: T5 | C30: Informational | D30: 340 | E30: 4 | F30: =IF(D30>0,E30/D30,0) | G30: 13 | H30: 11-20 | J30: Striking distance: expand + internal links | K30: 0.055 | L30: =MAX(0,ROUND(D30*K30-E30,0)) | M30: =IF(L30>=20,"High",IF(L30>=5,"Medium","Low"))
A31: can epoxy be applied over tiles | B31: T7 | C31: Informational | D31: 600 | E31: 2 | F31: =IF(D31>0,E31/D31,0) | G31: 28.4 | H31: 21+ | J31: Content gap: new section or page | K31: 0.026 | L31: =MAX(0,ROUND(D31*K31-E31,0)) | M31: =IF(L31>=20,"High",IF(L31>=5,"Medium","Low"))
... A51: i want a durable garage floor that looks good and is easy to clean what are my options | B51: T4 | C51: Informational | D51: 85 | E51: 1 | F51: =IF(D51>0,E51/D51,0) | G51: 12.9 | H51: 11-20 | J51: Striking distance: expand + internal links | K51: 0.055 | L51: =MAX(0,ROUND(D51*K51-E51,0)) | M51: =IF(L51>=20,"High",IF(L51>=5,"Medium","Low"))

Sheet Optimization Plan
A1: Topic | B1: Topic name | C1: Priority | D1: Target URL | E1: Page action | F1: Diagnosis | G1: Answer-first block (40-60 words) | H1: Words | I1: Question headings | J1: FAQ | K1: Table / steps / list | L1: Schema | M1: Internal links | N1: Off-site actions | O1: Check before publishing | P1: Status
A2: T1 | B2: Cost & price | C2: High | D2: https://www.coastlineepoxy.example/epoxy-flooring-cost/ | E2: Update existing page | F2: 8 cost questions, 6,755 impressions, average position 7.5. 'How much does epoxy flooring cost per square metre' ranks 3rd with CTR well under the expected rate (AI Overview likely). The page shows a price table but no sentence that answers the question on its own, so the summary quotes competitors. | G2: Epoxy flooring on the Gold Coast usually costs [$X-$Y] per square metre installed. A standard double garage (about 36 m²) runs [$A-$B] for a flake system. Price depends mostly on floor condition: crack repair, moisture treatment and grinding add [$C-$D]. Metallic finishes cost more than flake. | H2: =IF(LEN(TRIM(G2))=0,0,LEN(TRIM(G2))-LEN(SUBSTITUTE(TRIM(G2)," ",""))+1) | I2: - How much does epoxy flooring cost per square metre? - How much does it cost to epoxy a double garage? - Why is epoxy flooring so expensive? - What is the cheapest way to resurface a garage floor? | J2: Q: Why is epoxy flooring so expensive? A: Most of the cost is preparation: diamond grinding, crack repair and moisture testing, then two to three coats with cure time between them. Cheap jobs skip the prep, which is why they peel. Q: Is there a cheaper option than epoxy? A: Concrete paint or a DIY kit costs less up front but usually lasts [1-3] years in a garage that gets driven on. A professional flake system lasts [10-15+] years. | K2: | Garage size | Flake system | Metallic | Crack repair | | Single (18 m²) | [$] | [$] | from [$] | | Double (36 m²) | [$] | [$] | from [$] | | Triple (54 m²) | [$] | [$] | from [$] | | L2: Service, FAQPage, LocalBusiness | M2: - From /epoxy-garage-floors/ with anchor 'epoxy garage floor cost' - From /blog/diy-epoxy-vs-professional/ with anchor 'what a professional job costs' | N2: - Add a price range to the Google Business Profile services list - Pitch the price table to Gold Coast home-improvement roundups that AI cites for cost questions | O2: Confirm every price range [$X-$Y], [$A-$B], [$C-$D] and the lifespan years with the owner before publishing. | P2: To do
A3: T2 | B3: How long / timing | C3: High | D3: https://www.coastlineepoxy.example/epoxy-garage-floors/ | E3: Update existing page | F3: Lifespan and cure-time questions rank 2-4 (4,200 impressions) but 'how long does epoxy garage floor last' gets a small share of the clicks its position should earn: the AI Overview answers it. The page mentions durability only in a bullet list. | G3: A professionally installed epoxy garage floor lasts [10-20] years in a Queensland home garage; DIY kits usually last [1-3]. Lifespan depends on surface preparation, coating thickness and UV exposure near the door. You can walk on a new floor after [24] hours and park a car after [72] hours. | H3: =IF(LEN(TRIM(G3))=0,0,LEN(TRIM(G3))-LEN(SUBSTITUTE(TRIM(G3)," ",""))+1) | I3: - How long does an epoxy garage floor last? - How long after epoxy can I drive on it? - How long does epoxy take to cure before parking a car? | J3: Q: Does Queensland heat shorten epoxy life? A: Heat itself doesn't, but direct sun on standard epoxy can yellow it. A UV-stable topcoat on the first metre inside the door prevents that. | K3: 1. Day 0: install finished 2. Day 1: light foot traffic 3. Day 3: park cars 4. Day 7: full chemical resistance | L3: Service, FAQPage | M3: - From the homepage 'Garage floors' card with anchor 'how long epoxy lasts' | N3: - Answer the 'how long does garage epoxy last' threads on r/AusRenovation with your real numbers | O3: Confirm lifespan years and cure hours for the products used. | P3: To do
A4: T3 | B4: Choosing & comparing: company | C4: High | D4: https://www.coastlineepoxy.example/epoxy-garage-floors/ | E4: New section | F4: Ten 'is it worth it / which is best / what's the difference' prompts with 5,840 impressions at position 10. AI answers these with shortlists and comparison tables; the site has no comparison block and the 'company' prompts show buyers asking AI to compare installers. | G4: Epoxy is worth it for most garages that get daily car traffic: it resists oil and tyre marks, cleans in minutes and lasts [10-20] years. It's not worth it on floors with rising damp unless moisture is treated first. For the same budget, polyaspartic cures faster; polished concrete suits living areas. | H4: =IF(LEN(TRIM(G4))=0,0,LEN(TRIM(G4))-LEN(SUBSTITUTE(TRIM(G4)," ",""))+1) | I4: - Is epoxy flooring worth it for a garage? - What is the best epoxy for garage floors? - Epoxy vs polyaspartic: what's the difference? - How do I compare epoxy flooring companies on the Gold Coast? | J4: Q: What should I ask an epoxy installer before hiring? A: Ask how they prepare the slab (grinding, not acid etching), the coating thickness, the warranty in writing and for three recent local jobs you can see. | K4: | | Epoxy flake | Polyaspartic | Polished concrete | | Lifespan | [ ] | [ ] | [ ] | | Cure time | [ ] | [ ] | [ ] | | Price per m² | [ ] | [ ] | [ ] | | Best for | Garages | Fast turnaround | Living areas | | L4: FAQPage | M4: - From /blog/epoxy-vs-polished-concrete/ with anchor 'epoxy vs polyaspartic' | N4: - Get onto the 'best epoxy flooring Gold Coast' lists and directories that AI cites for these prompts - Ask recent customers for reviews that mention garage, lifespan and price | O4: Fill the comparison table with figures you can stand behind. | P4: To do
A5: T4 | B5: Cleaning & care | C5: Medium | D5: https://www.coastlineepoxy.example/blog/how-to-clean-epoxy-floors/ | E5: Update existing page | F5: Cleaning questions rank 3-8. The post is a long story before the method; AI needs the method in the first lines. | G5: Clean an epoxy garage floor with a soft mop, warm water and a pH-neutral cleaner. Sweep grit first, mop, then rinse so no film is left behind. Avoid vinegar, citrus and bleach-based cleaners on a regular basis: they dull the topcoat. Lift tyre marks with a degreaser and soft brush. | H5: =IF(LEN(TRIM(G5))=0,0,LEN(TRIM(G5))-LEN(SUBSTITUTE(TRIM(G5)," ",""))+1) | I5: - How do you clean an epoxy garage floor? - Can I use vinegar to clean my epoxy floor? - How do I remove tyre marks from epoxy? - What should you not use on epoxy floors? | K5: Do: soft mop, pH-neutral cleaner, rinse Don't: vinegar, citrus, steel wool, steam mops | L5: Article | M5: - From /epoxy-garage-floors/ 'After care' section | O5: Confirm which cleaners the coating supplier approves. | P5: To do
A6: T5 | B6: Problems & fixes: concrete | C6: Medium | D6: https://www.coastlineepoxy.example/epoxy-garage-floors/ | E6: New section | F6: Crack and peeling prompts sit at position 14 on average: the site never explains crack repair or why DIY epoxy peels. Long first-person prompts ('I have cracks in my garage floor...') show real worry before buying. | G6: Yes, epoxy can go over cracked concrete, but the cracks must be repaired first. Hairline cracks are filled with an epoxy or polyurea filler; moving cracks need a flexible joint so they don't telegraph through. Most peeling comes from skipped grinding or moisture, not the epoxy itself, so prep matters most. | H6: =IF(LEN(TRIM(G6))=0,0,LEN(TRIM(G6))-LEN(SUBSTITUTE(TRIM(G6)," ",""))+1) | I6: - Can you put epoxy over cracked concrete? - Should I fix cracks in concrete before epoxy? - Why does DIY epoxy peel off garage floors? | J6: Q: Why is my epoxy floor peeling after one year? A: Usually moisture coming up through the slab or a coating applied without grinding. It can be fixed, but the failed coating must be ground off first. | K6: 1. Moisture test the slab 2. Diamond grind 3. Fill and level cracks 4. Prime 5. Base coat + flake 6. UV-stable topcoat | L6: HowTo-style steps as an HTML list | M6: - From /blog/diy-epoxy-vs-professional/ with anchor 'how we fix cracks before coating' | N6: - Before/after photos of crack repair on Google Business Profile | O6: Add 2-3 real before/after photos with location and date. | P6: To do
A7: T6 | B7: Safety & standards | C7: Medium | D7: https://www.coastlineepoxy.example/flake-epoxy-flooring/ | E7: New section | F7: Slip and safety questions (1,910 impressions, position 14). Commercial buyers ask about food-safety standards; nothing on the site answers them. | G7: Epoxy can be slippery when wet if it has a smooth high-gloss finish. A flake system or an anti-slip additive in the topcoat gives a textured surface that grips well wet or dry. Once fully cured, epoxy is inert and not considered toxic; the fumes only matter during installation and curing. | H7: =IF(LEN(TRIM(G7))=0,0,LEN(TRIM(G7))-LEN(SUBSTITUTE(TRIM(G7)," ",""))+1) | I7: - Is epoxy flooring slippery when wet? - How do I make my epoxy floor less slippery? - Is epoxy flooring toxic once cured? | J7: Q: Does epoxy flooring meet food safety standards in Australia? A: Some commercial systems are rated for food areas. Ask for the product's data sheet and slip rating [rating] before you buy. | L7: FAQPage | M7: - From /commercial-epoxy-flooring/ with anchor 'slip-resistant epoxy' | O7: Confirm slip ratings and food-safety certifications for the actual products before naming them. | P7: To do
A8: T7 | B8: General epoxy questions | C8: Medium | D8: https://www.coastlineepoxy.example/epoxy-garage-floors/ | E8: New section | F8: Application questions (over tiles, pool decks, thickness) rank 21+: the topic isn't covered anywhere. | G8: Epoxy can go over tiles that are firmly bonded, once the glaze is ground back and the grout lines are filled, but tiles that move will crack the coating. Outdoor pool decks need a UV-stable, slip-resistant system rather than standard epoxy. A garage floor coating is usually [X-Y] microns thick. | H8: =IF(LEN(TRIM(G8))=0,0,LEN(TRIM(G8))-LEN(SUBSTITUTE(TRIM(G8)," ",""))+1) | I8: - Can epoxy be applied over tiles? - Can you epoxy a pool deck or outdoor patio? - How thick should an epoxy garage floor be? | L8: FAQPage | O8: Confirm the thickness range and whether the business does outdoor work at all. | P8: To do
A9: T8 | B9: Concrete: polished | C9: Medium | D9: https://www.coastlineepoxy.example/blog/epoxy-vs-polished-concrete/ | E9: Update existing page | F9: Two long comparison prompts at position 11. The post compares looks but not climate or humidity, which the prompts ask about. | G9: For a garage, epoxy usually beats polished concrete: it seals out oil and is easier to clean. For living areas in a humid climate like the Gold Coast, polished concrete breathes better and won't trap moisture. Epoxy costs less on garages; polished concrete suits large open-plan homes and needs resealing every [X] years. | H9: =IF(LEN(TRIM(G9))=0,0,LEN(TRIM(G9))-LEN(SUBSTITUTE(TRIM(G9)," ",""))+1) | I9: - Is polished concrete better than epoxy for a home? - Epoxy or polished concrete in a humid climate? | L9: Article | M9: - From /epoxy-flooring-cost/ with anchor 'epoxy vs polished concrete cost' | O9: Confirm resealing interval. | P9: To do
A10: T9 | B10: Commercial | C10: Low | H10: =IF(LEN(TRIM(G10))=0,0,LEN(TRIM(G10))-LEN(SUBSTITUTE(TRIM(G10)," ",""))+1) | P10: To do
A11: T10 | B11: Other AI-style queries | C11: Low | H11: =IF(LEN(TRIM(G11))=0,0,LEN(TRIM(G11))-LEN(SUBSTITUTE(TRIM(G11)," ",""))+1) | P11: To do

Sheet AI Visibility Plan
A1: AI visibility plan
A2: Fastest route first: unblock, fix the biggest leaks, then build and compound. Amber = yours to fill in.
A4: When | B4: Type | C4: Action | D4: Why / KPI | E4: Effort | F4: Impact | G4: Owner | H4: Status | I4: Date done
A5: Days 1-7 | B5: Quick win | C5: Check robots.txt and the Cloudflare bot settings: allow OAI-SearchBot, ChatGPT-User, PerplexityBot, Claude-SearchBot and Bingbot | D5: Blocked crawlers can't cite you; this takes 15 minutes | E5: Low | F5: High | H5: To do
A6: Days 1-7 | B6: Quick win | C6: Verify the site in Bing Webmaster Tools (import from GSC) and switch on IndexNow | D6: Several AI assistants lean on Bing's index; IndexNow pushes every update within minutes | E6: Low | F6: High | H6: To do
A7: Days 1-7 | B7: Quick win | C7: Add the T1 and T2 answer blocks + question headings to the cost and garage pages, then request indexing | D7: Top-3 rankings with low CTR: AI answers already pull from these pages, so a quotable passage can turn rankings into citations | E7: Low | F7: High | H7: To do
A8: Days 1-7 | B8: Quick win | C8: Rewrite the cost page title to promise the specific answer: 'Epoxy Flooring Cost Gold Coast: m² Prices + Real Jobs' | D8: AIO-flagged queries need a reason to click beyond the summary | E8: Low | F8: Medium | H8: To do
A9: Days 1-7 | B9: Quick win | C9: Save the master regex as a GSC filter and note this report's baseline (impressions, clicks, CTR) | D9: Monthly comparison shows what moved | E9: Low | F9: Medium | H9: To do
A10: Days 8-30 | B10: Plan | C10: Publish the full plans for T3-T6: comparison table, crack-repair steps, safety section, FAQ blocks with schema | D10: AI-style impressions on those pages; position of the top query per topic | E10: Medium | F10: High | H10: To do
A11: Days 8-30 | B11: Plan | C11: Outreach to the 'best epoxy flooring Gold Coast' lists and directories that AI cites for T3 prompts | D11: Number of cited sources that mention the brand | E11: Medium | F11: High | H11: To do
A12: Days 8-30 | B12: Plan | C12: Monthly prompt check: ask the top query of T1-T3 in ChatGPT, Perplexity, Gemini and Google AI Mode; log who is cited | D12: Cited yes/no per platform | E12: Low | F12: Medium | H12: To do
A13: Days 31-90 | B13: Plan | C13: Publish a small price survey: 'What 50 Gold Coast garage floors actually cost' from your own jobs | D13: Backlinks and citations to the survey | E13: High | F13: High | H13: To do
A14: Days 31-90 | B14: Plan | C14: Re-pull the master regex in GSC, compare with this baseline and move effort to the topics that grew | D14: AI-style clicks and CTR vs baseline | E14: Low | F14: Medium | H14: To do
A16: How to measure it
A17: - | C17: GSC: master regex filter, last 28 days vs this baseline - AI-style impressions, clicks, CTR
A18: - | C18: GA4 > Traffic acquisition > Session source matches regex chatgpt\.com|openai|perplexity|gemini\.google|copilot|claude\.ai
A19: - | C19: Prompt log: top query of T1-T3 asked monthly in ChatGPT, Perplexity, Gemini and AI Mode - cited yes/no, competitors cited

Sheet Method & Notes
A1: Method & notes
A2: Built with ai-queries-finder by Akif Qureshi | SEO Specialist - algoblueprints.com
A4: Date range | B4: Last 3 months (23 Jul - 21 Oct 2026)
A5: Search type | B5: Web
A6: Rows read | B6: 58
A7: AI-style threshold | B7: AI score >= 30 (tiers: High >= 50, Medium >= 30)
A8: Minimum impressions | B8: 1
A9: Brand terms excluded from topics | B9: coastline epoxy, coastline
A10: Locations (local intent) | B10: gold coast, southport, queensland, brisbane
A11: AI score | B11: Sum of the weights of every regex family the query matches, capped at 100 (see Regex Library).
A12: Topics | B12: Each AI-style, non-brand query joins the topic of its most common meaningful word across all AI-style queries. Words used by only one query go to 'Other'.
A13: Position buckets | B13: Top 3 / 4-10 / 11-20 / 21+ by average position.
A14: AI Overview likely | B14: Position <= 5 and CTR below 40% of the expected CTR for that position: the answer is probably being summarised above the results. A signal, not proof.
A15: Est. extra clicks | B15: Impressions x expected CTR at the target position (1 for top 3, 3 for 4-10, 5 for 11-20, 8 for 21+) minus current clicks. Conservative curve: 25% / 15% / 10% / 7% / 5.5% for 1-5.
A16: What GSC can't tell you | B16: Search Console doesn't label AI Mode, AI Overview or assistant traffic. These queries are found by their shape (length, phrasing, intent), so treat the list as the best available proxy. Very rare queries are anonymised by Google and never appear in the table.
A17: 1,000-row cap | B17: The GSC interface shows up to 1,000 rows per table. Run single regex families, or the API, for the full long tail.
